Workbook

Sheet 原始資料
A1: 編號 | B1: 一級類別代碼 | C1: 平台(細) | D1: 平台(歸類) | E1: 來源版/帳號 | F1: 標題／抱怨重點 | G1: 連結 | H1: 時間 | I1: 熱度(讚數) | J1: 立場 | K1: 情緒框架 | L1: 信度標記
A2: 1 | B2: A | C2: PTT 新竹板 | D2: PTT | E2: Hsinchu板 | F2: 怎麼整治騎在人行道的機車（點名外送員、檢舉舉證難） | G2: https://www.ptt.cc/bbs/Hsinchu/M.1733025008.A.934.html | H2: 2024-12 | J2: 行人路權方 | K2: 無力感 | L2: 原站可查核
A3: 2 | B3: A | C3: PTT Road板 | D3: PTT | E3: Road板 | F3: 駕駛人無視 人行道淪「汽機車道」（無高低差、要求物理隔離） | G3: https://www.ptt.cc/bbs/Road/M.1659087904.A.EC6.html | H3: 2022-07 | J3: 行人路權方 | K3: 憤怒 | L3: 原站可查核
A4: 3 | B4: A | C4: PTT 高雄板 | D4: PTT | E4: Kaohsiung板 | F4: 瑞隆路重鋪後騎車更危險（違停未取締是主因） | G4: https://www.ptt.cc/bbs/Kaohsiung/M.1715248047.A.25C.html | H4: 2024-05 | J4: 機車騎士方 | K4: 無力感 | L4: 原站可查核
A5: 4 | B5: A | C5: PTT WomenTalk | D5: PTT | E5: WomenTalk板 | F5: 自行車不能騎在人行道上（按鈴驅趕行人） | G5: https://www.ptt.cc/bbs/WomenTalk/M.1701292817.A.D94.html | H5: 2023-11 | J5: 行人路權方 | K5: 憤怒 | L5: 原站可查核
A6: 5 | B6: A | C6: PTT biker板 | D6: PTT | E6: biker板 | F6: 人行道上的機車格（牽車出格被開單、選擇性執法） | G6: https://www.ptt.cc/bbs/biker/M.1681403175.A.BE4.html | H6: 2023-04 | J6: 機車騎士方 | K6: 無力感 | L6: 原站可查核
A7: 6 | B7: A | C7: PTT biker板 | D7: PTT | E7: biker板 | F7: 停騎樓還是人行道（機車族無處可停的兩難） | G7: https://www.ptt.cc/bbs/biker/M.1652932435.A.DA7.html | H7: 2022-05 | J7: 機車騎士方 | K7: 無力感 | L7: 原站可查核
A8: 7 | B8: A | C8: Dcard 心情板 | D8: Dcard | E8: mood板 | F8: 台灣人違停比起紅線更愛停人行道的邏輯 | G8: https://www.dcard.tw/f/mood/p/259866980 | H8: 約2025 | J8: 行人路權方 | K8: 憤怒 | L8: 摘要
A9: 8 | B9: A | C9: Dcard 閒聊板 | D9: Dcard | E9: talk板 | F9: 人行道機車格，你用騎的還用牽的？ | G9: https://www.dcard.tw/f/talk/p/254614839 | H9: 約2024 | J9: 機車騎士方 | K9: 嘲諷/迷因化 | L9: 摘要
A10: 9 | B10: A | C10: Dcard 心情板 | D10: Dcard | E10: mood板 | F10: 機車格畫在人行道到底是怎樣 | G10: https://www.dcard.tw/f/mood/p/229321860 | H10: 約2019-20 | J10: 行人路權方 | K10: 憤怒 | L10: 摘要
A11: 10 | B11: A | C11: Dcard 成大板 | D11: Dcard | E11: ncku板 | F11: 最簡單檢舉機車騎人行道的流程（學生自力救濟教學） | G11: https://www.dcard.tw/f/ncku/p/242391089 | H11: 約2023 | J11: 行人路權方 | K11: 無力感 | L11: 摘要
A12: 11 | B12: A | C12: Dcard 成大板 | D12: Dcard | E12: ncku板 | F12: 機車與人行道（呼籲尊重行人路權） | G12: https://www.dcard.tw/f/ncku/p/240225089 | H12: 約2023 | J12: 行人路權方 | K12: 憤怒 | L12: 摘要
A13: 12 | B13: A | C13: Dcard 機車板 | D13: Dcard | E13: vehicle板 | F13: 關於人行道上的停車格（設計逼人騎上人行道） | G13: https://www.dcard.tw/f/vehicle/p/256482507 | H13: 約2024-25 | J13: 機車騎士方 | K13: 無力感 | L13: 摘要
A14: 13 | B14: A | C14: Threads | D14: Threads | E14: @wonmon5 | F14: 機車在人行道「用腳滑不行嗎」（騎士方挑釁） | G14: https://www.threads.com/@wonmon5/post/C9wUMqISFU3 | H14: 2024-07-22 | I14: 263 | J14: 機車騎士方 | K14: 嘲諷/迷因化 | L14: 全文
A15: 14 | B15: B | C15: Threads | D15: Threads | E15: @sightiffick | F15: 車停人行道，行人只能走馬路，明明有停車格 | G15: https://www.threads.com/@sightiffick/post/DGIE-TdPG9j/ | H15: 2025-02-16 | I15: 10400 | J15: 行人路權方 | K15: 憤怒 | L15: 全文
A16: 15 | B16: B | C16: Threads | D16: Threads | E16: @doreeeeeeeeeeeen | F16: 車停斑馬線逾十分鐘，因檢舉限縮無法證明時間軸 | G16: https://www.threads.com/@doreeeeeeeeeeeen/post/DFteMrih_6k | H16: 2025-02-05 | I16: 51 | J16: 行人路權方 | K16: 無力感 | L16: 全文
A17: 16 | B17: B | C17: Dcard 機車板 | D17: Dcard | E17: vehicle板 | F17: 婦人待轉區當車格，勸導後改停人行道 | G17: https://www.dcard.tw/f/vehicle/p/236756672 | H17: 約2021 | J17: 中立敘事 | K17: 無力感 | L17: 摘要
A18: 17 | B18: B | C18: Mobile01 汽車版 | D18: Mobile01 | E18: 汽車消費經驗分享版 | F18: 人行道違停無法檢舉／立委喊恢復檢舉 | G18: https://www.mobile01.com/topicdetail.php?f=294&t=6714823 | H18: 2023初/2024-06 | J18: 行人路權方 | K18: 無力感 | L18: 摘要
A19: 18 | B19: C | C19: PTT 雙和板 | D19: PTT | E19: ShuangHe板 | F19: 佔用騎樓檢舉四年搞不定（250封檢舉信無效） | G19: https://www.ptt.cc/bbs/ShuangHe/M.1707044476.A.B55.html | H19: 2024-02 | J19: 行人路權方 | K19: 無力感 | L19: 原站可查核
A20: 19 | B20: C | C20: PTT 台南板 | D20: PTT | E20: Tainan板 | F20: 騎樓議題／標線型人行道與攤商票倉矛盾 | G20: https://www.ptt.cc/bbs/Tainan/M.1654617893.A.048.html | H20: 2022-06 | J20: 中立敘事 | K20: 剝奪感/城鄉落差 | L20: 原站可查核
A21: 20 | B21: C | C21: PTT 台中板 | D21: PTT | E21: TaichungBun板 | F21: 大坑9號步道攤販終於拆除（積怨已久） | G21: https://www.ptt.cc/bbs/TaichungBun/M.1678258216.A.83F.html | H21: 2023-03 | J21: 行人路權方 | K21: 無力感 | L21: 原站可查核
A22: 21 | B22: C | C22: Mobile01 居家/台北版 | D22: Mobile01 | E22: 居家版 | F22: 騎樓佔用陳情無效、高低差長者身障難行 | G22: https://www.mobile01.com/topicdetail.php?f=37&t=6035881 | H22: 2019-21 | J22: 身障/視障方 | K22: 無力感 | L22: 摘要
A23: 22 | B23: C | C23: Dcard 心情板 | D23: Dcard | E23: mood板 | F23: 機車停放騎樓之遭遇（留言：身障者要走哪？） | G23: https://www.dcard.tw/f/mood/p/232161658 | H23: 約2020 | J23: 身障/視障方 | K23: 憤怒 | L23: 摘要
A24: 23 | B24: C | C24: Dcard 閒聊/逢甲板 | D24: Dcard | E24: talk/fcu板 | F24: 騎樓／人行道抽菸、菸蒂痛點 | G24: https://www.dcard.tw/f/talk/p/240429608 | H24: 約2022-23 | J24: 行人路權方 | K24: 憤怒 | L24: 摘要
A25: 24 | B25: C | C25: TVBS/恆安法律 | D25: 其他(法律/YouTube) | E25: 新聞/法律 | F25: 店家管門前反遭檢舉「占用騎樓」開罰 | G25: https://www.youtube.com/watch?v=6MvYz8gfAfI | H25: 約2023 | J25: 店家/里長方 | K25: 無力感 | L25: 新聞引述
A26: 25 | B26: D | C26: PTT 八卦板 | D26: PTT | E26: Gossiping板 | F26: 為啥台灣有地卻不愛蓋人行道（優先畫機車道停車格） | G26: https://www.ptt.cc/bbs/Gossiping/M.1721106452.A.CA0.html | H26: 2024-07 | J26: 行人路權方 | K26: 羞辱感/國際比較 | L26: 原站可查核
A27: 26 | B27: D | C27: PTT WomenTalk | D27: PTT | E27: WomenTalk板 | F27: 台灣為啥不蓋人行道（「蓋人行道沒選票」） | G27: https://www.ptt.cc/bbs/WomenTalk/M.1722500270.A.D37.html | H27: 2024-08 | J27: 行人路權方 | K27: 剝奪感/城鄉落差 | L27: 原站可查核
A28: 27 | B28: D | C28: PTT 桃園板 | D28: PTT | E28: Taoyuan板 | F28: 舊市區人行道幾乎沒有、議員反對改油漆標線 | G28: https://www.ptt.cc/bbs/Taoyuan/M.1692004313.A.C4A.html | H28: 2023-08 | J28: 行人路權方 | K28: 剝奪感/城鄉落差 | L28: 原站可查核
... A33: 32 | B33: D | C33: Dcard 汽機車板 | D33: Dcard | E33: vehicle板 | F33: 台灣路很寬，人行道呢？（對比日本，重車輕人） | G33: https://www.dcard.tw/f/vehicle/p/231229443 | H33: 約2020 | J33: 行人路權方 | K33: 羞辱感/國際比較 | L33: 摘要
A34: 33 | B34: D | C34: Threads | D34: Threads | E34: @d.p.willy | F34: 一張圖解釋台灣人行道為何不普及 | G34: https://www.threads.com/@d.p.willy/post/DJ1sPjHSRXF | H34: 2025-05-19 | I34: 10700 | J34: 行人路權方 | K34: 剝奪感/城鄉落差 | L34: 全文
A35: 34 | B35: E | C35: PTT 新竹板 | D35: PTT | E35: Hsinchu板 | F35: 標線人行道劃一年被塗銷改停車格（綠標最易塗銷） | G35: https://www.ptt.cc/bbs/Hsinchu/M.1687913093.A.206.html | H35: 2023-06 | J35: 行人路權方 | K35: 憤怒 | L35: 原站可查核
A36: 35 | B36: E | C36: PTT car板 | D36: PTT | E36: car板 | F36: 問題在人行道／回文提電箱電桿擋道 | G36: https://www.ptt.cc/bbs/car/M.1686244646.A.BB5.html | H36: 2023-06 | J36: 行人路權方 | K36: 無力感 | L36: 原站可查核
A37: 36 | B37: E | C37: PTT home-sale | D37: PTT | E37: home-sale板 | F37: 步行多久算遠（閃車繞障礙，步行品質差） | G37: https://www.ptt.cc/bbs/home-sale/M.1737985112.A.009.html | H37: 2025-01 | J37: 行人路權方 | K37: 無力感 | L37: 原站可查核
A38: 37 | B38: E | C38: 公視新聞 | D38: 新聞媒體 | E38: 新聞 | F38: 標線型人行道採訪：線太不明顯、車照停 | G38: https://news.pts.org.tw/article/523348 | H38: 2021-04-26 | J38: 中立敘事 | K38: 無力感 | L38: 新聞引述
A39: 38 | B39: E | C39: 中國時報/立院 | D39: 新聞媒體 | E39: 新聞/立院 | F39: 標線型像「障礙賽道」、議員批浪費公帑 | G39: https://www.chinatimes.com/newspapers/20230306000618-260106 | H39: 2023-03 | J39: 政府/中立敘事 | K39: 嘲諷/迷因化 | L39: 新聞引述
A40: 39 | B40: E | C40: 眼底城事/關鍵評論 | D40: 倡議媒體/團體 | E40: 倡議媒體 | F40: 民調92%民眾不滿人行環境、寬度不達標 | G40: https://eyesonplace.net/2020/11/25/15768/ | H40: 2020-11 | J40: 倡議團體 | K40: 剝奪感/城鄉落差 | L40: 量化調查
A41: 40 | B41: E | C41: Threads | D41: Threads | E41: @motorisland1688 | F41: 綠色標線人行道對人車真的安全嗎 | G41: https://www.threads.com/@motorisland1688/post/C_N6fWTS65G | H41: 2024-08-28 | I41: 230 | J41: 行人路權方 | K41: 嘲諷/迷因化 | L41: 全文
A42: 41 | B42: E | C42: Dcard→Yahoo | D42: Dcard | E42: 新聞轉載 | F42: 墾丁綠色人行道忽大忽小、擺攤設變電箱 | G42: https://tw.news.yahoo.com/ | H42: 2025-01-30 | J42: 行人路權方 | K42: 嘲諷/迷因化 | L42: 新聞引述
A43: 42 | B43: E | C43: Threads | D43: Threads | E43: @vision.zero.tainan | F43: 電線桿長在人行道中央、缺「設施帶」整合 | G43: https://www.threads.com/@vision.zero.tainan/post/DGTXRpKyIH5 | H43: 2025-02-20 | I43: 24 | J43: 倡議團體 | K43: 嘲諷/迷因化 | L43: 全文
A44: 43 | B44: E | C44: Threads | D44: Threads | E44: @capybara_1204 | F44: 人行道+自行車道=救護車道（迷因化嘲諷） | G44: https://www.threads.com/@capybara_1204/post/DYb7Vvaj3Y4 | H44: 2026-05-17 | I44: 21100 | J44: 行人路權方 | K44: 嘲諷/迷因化 | L44: 全文
...

Sheet 編碼架構
A1: 類別代碼 | B1: 類別名稱 | C1: 操作型定義 | D1: 代表案例編號
A2: A | B2: A. 佔用型—機車騎上/停上人行道 | C2: 機車（含自行車）直接騎乘或停放於人行道上，導致行人與慢車爭道；含機車格劃設於人行道之制度性矛盾。 | D2: 1, 2, 13
A3: B | B3: B. 佔用型—汽車違停逼行人上馬路 | C3: 汽車違停佔用人行道或斑馬線，迫使行人繞行或走上車道；含違規檢舉制度限縮的挫折。 | D3: 14, 15
A4: C | B4: C. 佔用型—騎樓被店家/攤販/雜物佔用 | C4: 騎樓因公私產權模糊，被店家、攤販、雜物、機車長期佔用，行人（尤其身障者）無法通行。 | D4: 18, 22
A5: D | B5: D. 缺席型—根本沒有人行道 | C5: 該路段根本未設置人行道，行人被迫與車輛混流；常見於非六都或舊市區，並涉及城鄉與國際比較。 | D5: 25, 29
A6: E | B6: E. 設計失敗型—標線型人行道與障礙物 | C6: 已設置之人行道（尤其標線型／綠色鋪面）因未加高、無阻隔、遭電箱電桿路樹等公共設施切割，形同虛設。 | D6: 34, 43
A7: F | B7: F. 制度挫折型—檢舉限縮/罰則/主管機關 | C7: 違規檢舉機制限縮、罰則過輕、道路主管機關權責分散，使民眾陳情/檢舉徒勞無功。 | D7: 18(交叉), 46
A8: G | B8: G. 安全恐懼型—事故/身障/國賠 | C8: 因人行道缺陷（高低差、路阻、鋪面破損）造成之死傷事故、身心障礙者行動困境、國家賠償案件。 | D8: 49, 53, 55
A9: H | B9: H. 反彈方—工程衝突對照組（非行人路權視角） | C9: 人行道／標線型人行道／機車退出騎樓等工程政策，引發汽機車族、店家、里長之反向民怨（對照組，供衝突結構分析）。 | D9: 56, 59
A12: 立場分類
A13: 行人路權方 | B13: 以步行者/一般民眾視角發言，主張改善人行道、加強執法
A14: 機車騎士方 | B14: 以機車使用者視角發言，含停車困擾、檢舉挫折、亦含挑釁言論
A15: 汽車駕駛方 | B15: 以汽車使用者視角發言，反對車道縮減
A16: 店家/里長方 | B16: 以沿街店家或地方民代視角，關切生意與工程溝通
A17: 身障/視障方 | B17: 身心障礙者或代言之無障礙倡議視角
A18: 政府/中立敘事 | B18: 官方回應、記者中立敘述或未表態之陳述
A19: 中立敘事 | B19: 純敘述事件，未明顯代入特定立場
A20: 倡議團體 | B20: 路權/人本交通倡議組織或媒體之發言
A22: 情緒框架分類
A23: 憤怒 | B23: 對佔用者、違規者、失能制度的直接譴責
A24: 無力感 | B24: 檢舉/陳情/勸導無效後的挫敗與放棄感
A25: 嘲諷/迷因化 | B25: 以反諷、迷因、玩笑口吻消費荒謬設計（常見高互動貼文）
A26: 恐懼 | B26: 因死傷事故、人身安全威脅產生的不安
A27: 剝奪感/城鄉落差 | B27: 將自身處境與台北或其他都會區比較後的相對剝奪
A28: 羞辱感/國際比較 | B28: 與日本、東南亞、歐美等國比較後產生的國族/文明羞恥感

Sheet 編碼分析
A1: 「人行道」社群痛點編碼分析
A2: 資料來源：原始資料工作表（N=60則，2019–2026）
A4: 表一、一級類別次數分配
A5: 類別代碼 | B5: 類別名稱 | C5: 次數 | D5: 百分比
A6: A | B6: A. 佔用型—機車騎上/停上人行道 | C6: =COUNTIF(原始資料!$B$2:$B$61,A6) | D6: =C6/SUM($C$6:$C$13)
A7: B | B7: B. 佔用型—汽車違停逼行人上馬路 | C7: =COUNTIF(原始資料!$B$2:$B$61,A7) | D7: =C7/SUM($C$6:$C$13)
A8: C | B8: C. 佔用型—騎樓被店家/攤販/雜物佔用 | C8: =COUNTIF(原始資料!$B$2:$B$61,A8) | D8: =C8/SUM($C$6:$C$13)
A9: D | B9: D. 缺席型—根本沒有人行道 | C9: =COUNTIF(原始資料!$B$2:$B$61,A9) | D9: =C9/SUM($C$6:$C$13)
A10: E | B10: E. 設計失敗型—標線型人行道與障礙物 | C10: =COUNTIF(原始資料!$B$2:$B$61,A10) | D10: =C10/SUM($C$6:$C$13)
A11: F | B11: F. 制度挫折型—檢舉限縮/罰則/主管機關 | C11: =COUNTIF(原始資料!$B$2:$B$61,A11) | D11: =C11/SUM($C$6:$C$13)
A12: G | B12: G. 安全恐懼型—事故/身障/國賠 | C12: =COUNTIF(原始資料!$B$2:$B$61,A12) | D12: =C12/SUM($C$6:$C$13)
A13: H | B13: H. 反彈方—工程衝突對照組（非行人路權視角） | C13: =COUNTIF(原始資料!$B$2:$B$61,A13) | D13: =C13/SUM($C$6:$C$13)
B14: 合計 | C14: =SUM(C6:C13) | D14: =SUM(D6:D13)
A17: 表二、平台 × 痛點類別 交叉分析
A18: 平台 | B18: A | C18: B | D18: C | E18: D | F18: E | G18: F | H18: G | I18: H | J18: 總計
A19: PTT | B19: =COUNTIFS(原始資料!$D$2:$D$61,$A19,原始資料!$B$2:$B$61,B$18) | C19: =COUNTIFS(原始資料!$D$2:$D$61,$A19,原始資料!$B$2:$B$61,C$18) | D19: =COUNTIFS(原始資料!$D$2:$D$61,$A19,原始資料!$B$2:$B$61,D$18) | E19: =COUNTIFS(原始資料!$D$2:$D$61,$A19,原始資料!$B$2:$B$61,E$18) | F19: =COUNTIFS(原始資料!$D$2:$D$61,$A19,原始資料!$B$2:$B$61,F$18) | G19: =COUNTIFS(原始資料!$D$2:$D$61,$A19,原始資料!$B$2:$B$61,G$18) | H19: =COUNTIFS(原始資料!$D$2:$D$61,$A19,原始資料!$B$2:$B$61,H$18) | I19: =COUNTIFS(原始資料!$D$2:$D$61,$A19,原始資料!$B$2:$B$61,I$18) | J19: =SUM(B19:I19)
A20: Dcard | B20: =COUNTIFS(原始資料!$D$2:$D$61,$A20,原始資料!$B$2:$B$61,B$18) | C20: =COUNTIFS(原始資料!$D$2:$D$61,$A20,原始資料!$B$2:$B$61,C$18) | D20: =COUNTIFS(原始資料!$D$2:$D$61,$A20,原始資料!$B$2:$B$61,D$18) | E20: =COUNTIFS(原始資料!$D$2:$D$61,$A20,原始資料!$B$2:$B$61,E$18) | F20: =COUNTIFS(原始資料!$D$2:$D$61,$A20,原始資料!$B$2:$B$61,F$18) | G20: =COUNTIFS(原始資料!$D$2:$D$61,$A20,原始資料!$B$2:$B$61,G$18) | H20: =COUNTIFS(原始資料!$D$2:$D$61,$A20,原始資料!$B$2:$B$61,H$18) | I20: =COUNTIFS(原始資料!$D$2:$D$61,$A20,原始資料!$B$2:$B$61,I$18) | J20: =SUM(B20:I20)
A21: Threads | B21: =COUNTIFS(原始資料!$D$2:$D$61,$A21,原始資料!$B$2:$B$61,B$18) | C21: =COUNTIFS(原始資料!$D$2:$D$61,$A21,原始資料!$B$2:$B$61,C$18) | D21: =COUNTIFS(原始資料!$D$2:$D$61,$A21,原始資料!$B$2:$B$61,D$18) | E21: =COUNTIFS(原始資料!$D$2:$D$61,$A21,原始資料!$B$2:$B$61,E$18) | F21: =COUNTIFS(原始資料!$D$2:$D$61,$A21,原始資料!$B$2:$B$61,F$18) | G21: =COUNTIFS(原始資料!$D$2:$D$61,$A21,原始資料!$B$2:$B$61,G$18) | H21: =COUNTIFS(原始資料!$D$2:$D$61,$A21,原始資料!$B$2:$B$61,H$18) | I21: =COUNTIFS(原始資料!$D$2:$D$61,$A21,原始資料!$B$2:$B$61,I$18) | J21: =SUM(B21:I21)
A22: Mobile01 | B22: =COUNTIFS(原始資料!$D$2:$D$61,$A22,原始資料!$B$2:$B$61,B$18) | C22: =COUNTIFS(原始資料!$D$2:$D$61,$A22,原始資料!$B$2:$B$61,C$18) | D22: =COUNTIFS(原始資料!$D$2:$D$61,$A22,原始資料!$B$2:$B$61,D$18) | E22: =COUNTIFS(原始資料!$D$2:$D$61,$A22,原始資料!$B$2:$B$61,E$18) | F22: =COUNTIFS(原始資料!$D$2:$D$61,$A22,原始資料!$B$2:$B$61,F$18) | G22: =COUNTIFS(原始資料!$D$2:$D$61,$A22,原始資料!$B$2:$B$61,G$18) | H22: =COUNTIFS(原始資料!$D$2:$D$61,$A22,原始資料!$B$2:$B$61,H$18) | I22: =COUNTIFS(原始資料!$D$2:$D$61,$A22,原始資料!$B$2:$B$61,I$18) | J22: =SUM(B22:I22)
A23: 新聞媒體 | B23: =COUNTIFS(原始資料!$D$2:$D$61,$A23,原始資料!$B$2:$B$61,B$18) | C23: =COUNTIFS(原始資料!$D$2:$D$61,$A23,原始資料!$B$2:$B$61,C$18) | D23: =COUNTIFS(原始資料!$D$2:$D$61,$A23,原始資料!$B$2:$B$61,D$18) | E23: =COUNTIFS(原始資料!$D$2:$D$61,$A23,原始資料!$B$2:$B$61,E$18) | F23: =COUNTIFS(原始資料!$D$2:$D$61,$A23,原始資料!$B$2:$B$61,F$18) | G23: =COUNTIFS(原始資料!$D$2:$D$61,$A23,原始資料!$B$2:$B$61,G$18) | H23: =COUNTIFS(原始資料!$D$2:$D$61,$A23,原始資料!$B$2:$B$61,H$18) | I23: =COUNTIFS(原始資料!$D$2:$D$61,$A23,原始資料!$B$2:$B$61,I$18) | J23: =SUM(B23:I23)
A24: 倡議媒體/團體 | B24: =COUNTIFS(原始資料!$D$2:$D$61,$A24,原始資料!$B$2:$B$61,B$18) | C24: =COUNTIFS(原始資料!$D$2:$D$61,$A24,原始資料!$B$2:$B$61,C$18) | D24: =COUNTIFS(原始資料!$D$2:$D$61,$A24,原始資料!$B$2:$B$61,D$18) | E24: =COUNTIFS(原始資料!$D$2:$D$61,$A24,原始資料!$B$2:$B$61,E$18) | F24: =COUNTIFS(原始資料!$D$2:$D$61,$A24,原始資料!$B$2:$B$61,F$18) | G24: =COUNTIFS(原始資料!$D$2:$D$61,$A24,原始資料!$B$2:$B$61,G$18) | H24: =COUNTIFS(原始資料!$D$2:$D$61,$A24,原始資料!$B$2:$B$61,H$18) | I24: =COUNTIFS(原始資料!$D$2:$D$61,$A24,原始資料!$B$2:$B$61,I$18) | J24: =SUM(B24:I24)
A25: 官方平台(join.gov.tw) | B25: =COUNTIFS(原始資料!$D$2:$D$61,$A25,原始資料!$B$2:$B$61,B$18) | C25: =COUNTIFS(原始資料!$D$2:$D$61,$A25,原始資料!$B$2:$B$61,C$18) | D25: =COUNTIFS(原始資料!$D$2:$D$61,$A25,原始資料!$B$2:$B$61,D$18) | E25: =COUNTIFS(原始資料!$D$2:$D$61,$A25,原始資料!$B$2:$B$61,E$18) | F25: =COUNTIFS(原始資料!$D$2:$D$61,$A25,原始資料!$B$2:$B$61,F$18) | G25: =COUNTIFS(原始資料!$D$2:$D$61,$A25,原始資料!$B$2:$B$61,G$18) | H25: =COUNTIFS(原始資料!$D$2:$D$61,$A25,原始資料!$B$2:$B$61,H$18) | I25: =COUNTIFS(原始資料!$D$2:$D$61,$A25,原始資料!$B$2:$B$61,I$18) | J25: =SUM(B25:I25)
A26: 其他(法律/YouTube) | B26: =COUNTIFS(原始資料!$D$2:$D$61,$A26,原始資料!$B$2:$B$61,B$18) | C26: =COUNTIFS(原始資料!$D$2:$D$61,$A26,原始資料!$B$2:$B$61,C$18) | D26: =COUNTIFS(原始資料!$D$2:$D$61,$A26,原始資料!$B$2:$B$61,D$18) | E26: =COUNTIFS(原始資料!$D$2:$D$61,$A26,原始資料!$B$2:$B$61,E$18) | F26: =COUNTIFS(原始資料!$D$2:$D$61,$A26,原始資料!$B$2:$B$61,F$18) | G26: =COUNTIFS(原始資料!$D$2:$D$61,$A26,原始資料!$B$2:$B$61,G$18) | H26: =COUNTIFS(原始資料!$D$2:$D$61,$A26,原始資料!$B$2:$B$61,H$18) | I26: =COUNTIFS(原始資料!$D$2:$D$61,$A26,原始資料!$B$2:$B$61,I$18) | J26: =SUM(B26:I26)
A27: 總計 | B27: =SUM(B19:B26) | C27: =SUM(C19:C26) | D27: =SUM(D19:D26) | E27: =SUM(E19:E26) | F27: =SUM(F19:F26) | G27: =SUM(G19:G26) | H27: =SUM(H19:H26) | I27: =SUM(I19:I26) | J27: =SUM(J19:J26)
A30: 表三、發言立場次數分配
A31: 立場 | B31: 次數 | C31: 百分比
A32: 行人路權方 | B32: =COUNTIF(原始資料!$J$2:$J$61,A32) | C32: =B32/SUM($B$32:$B$39)
A33: 機車騎士方 | B33: =COUNTIF(原始資料!$J$2:$J$61,A33) | C33: =B33/SUM($B$32:$B$39)
A34: 汽車駕駛方 | B34: =COUNTIF(原始資料!$J$2:$J$61,A34) | C34: =B34/SUM($B$32:$B$39)
A35: 店家/里長方 | B35: =COUNTIF(原始資料!$J$2:$J$61,A35) | C35: =B35/SUM($B$32:$B$39)
A36: 身障/視障方 | B36: =COUNTIF(原始資料!$J$2:$J$61,A36) | C36: =B36/SUM($B$32:$B$39)
A37: 政府/中立敘事 | B37: =COUNTIF(原始資料!$J$2:$J$61,A37) | C37: =B37/SUM($B$32:$B$39)
A38: 中立敘事 | B38: =COUNTIF(原始資料!$J$2:$J$61,A38) | C38: =B38/SUM($B$32:$B$39)
A39: 倡議團體 | B39: =COUNTIF(原始資料!$J$2:$J$61,A39) | C39: =B39/SUM($B$32:$B$39)
A40: 合計 | B40: =SUM(B32:B39) | C40: =SUM(C32:C39)
A43: 表四、情緒框架次數分配
A44: 情緒框架 | B44: 次數 | C44: 百分比
A45: 憤怒 | B45: =COUNTIF(原始資料!$K$2:$K$61,A45) | C45: =B45/SUM($B$45:$B$50)
A46: 無力感 | B46: =COUNTIF(原始資料!$K$2:$K$61,A46) | C46: =B46/SUM($B$45:$B$50)
A47: 嘲諷/迷因化 | B47: =COUNTIF(原始資料!$K$2:$K$61,A47) | C47: =B47/SUM($B$45:$B$50)
...
